<?xml version="1.0" encoding="utf-8"?>
<!-- This URDF was automatically created by SolidWorks to URDF Exporter! Originally created by Stephen Brawner (brawner@gmail.com) 
     Commit Version: 1.6.0-4-g7f85cfe  Build Version: 1.6.7995.38578
     For more information, please see http://wiki.ros.org/sw_urdf_exporter -->
<robot
  name="gripper">
  <link
    name="gripper_head">
    <inertial>
      <origin
        xyz="0.00323055318421452 0.00571269700091375 0.00847802343130645"
        rpy="0 0 0" />
      <mass
        value="0.000248817240273109" />
      <inertia
        ixx="1.24533619200803E-09"
        ixy="3.98193864519775E-14"
        ixz="-4.71443407373705E-13"
        iyy="1.85586084685055E-09"
        iyz="4.91941940817118E-11"
        izz="1.72781442655061E-09" />
    </inertial>
    <visual>
      <origin
        xyz="0 0 0"
        rpy="0 0 0" />
      <geometry>
        <mesh
          filename="package://gripper/meshes/gripper_head.STL" />
      </geometry>
      <material
        name="">
        <color
          rgba="0.792156862745098 0.819607843137255 0.933333333333333 1" />
      </material>
    </visual>
    <collision>
      <origin
        xyz="0 0 0"
        rpy="0 0 0" />
      <geometry>
        <mesh
          filename="package://gripper/meshes/gripper_head.STL" />
      </geometry>
    </collision>
  </link>
  <link
    name="left_gripper_link">
    <inertial>
      <origin
        xyz="0.00257506972135058 2.01670223389577E-05 0.0106733481729336"
        rpy="0 0 0" />
      <mass
        value="0.000110343960618183" />
      <inertia
        ixx="5.35540734738421E-10"
        ixy="2.72556779627456E-15"
        ixz="-2.39067108113678E-13"
        iyy="6.68288834173598E-10"
        iyz="-3.61159619464986E-15"
        izz="5.67832018123353E-10" />
    </inertial>
    <visual>
      <origin
        xyz="0 0 0"
        rpy="0 0 0" />
      <geometry>
        <mesh
          filename="package://gripper/meshes/left_gripper_link.STL" />
      </geometry>
      <material
        name="">
        <color
          rgba="0.792156862745098 0.819607843137255 0.933333333333333 1" />
      </material>
    </visual>
    <collision>
      <origin
        xyz="0 0 0"
        rpy="0 0 0" />
      <geometry>
        <mesh
          filename="package://gripper/meshes/left_gripper_link.STL" />
      </geometry>
    </collision>
  </link>
  <joint
    name="left_gripper_joint"
    type="prismatic">
    <origin
      xyz="-0.0044172 -0.0017529 0.0065639"
      rpy="1.5708 0 0" />
    <parent
      link="gripper_head" />
    <child
      link="left_gripper_link" />
    <axis
      xyz="1 0 0" />
    <limit
      lower="-0.0033"
      upper="0"
      effort="0"
      velocity="0" />
  </joint>
  <link
    name="right_gripper_link">
    <inertial>
      <origin
        xyz="0.0116249302786494 -0.000222760534768027 0.0106733481729336"
        rpy="0 0 0" />
      <mass
        value="0.000110343960618183" />
      <inertia
        ixx="5.35540734738421E-10"
        ixy="2.72556779624708E-15"
        ixz="2.39067108113796E-13"
        iyy="6.68288834173598E-10"
        iyz="3.61159619452802E-15"
        izz="5.67832018123353E-10" />
    </inertial>
    <visual>
      <origin
        xyz="0 0 0"
        rpy="0 0 0" />
      <geometry>
        <mesh
          filename="package://gripper/meshes/right_gripper_link.STL" />
      </geometry>
      <material
        name="">
        <color
          rgba="0.792156862745098 0.819607843137255 0.933333333333333 1" />
      </material>
    </visual>
    <collision>
      <origin
        xyz="0 0 0"
        rpy="0 0 0" />
      <geometry>
        <mesh
          filename="package://gripper/meshes/right_gripper_link.STL" />
      </geometry>
    </collision>
  </link>
  <joint
    name="right_gripper_joint"
    type="prismatic">
    <origin
      xyz="-0.0033172 -0.0017529 0.0065639"
      rpy="1.5708 0 0" />
    <parent
      link="gripper_head" />
    <child
      link="right_gripper_link" />
    <axis
      xyz="1 0 0" />
    <limit
      lower="-0.0033"
      upper="0"
      effort="0"
      velocity="0" />
  </joint>
</robot>